<?xml version="1.0"?>
<robot xmlns:xacro="http://www.ros.org/wiki/xacro" name="qube">

  <!-- Define Properties for Flexibility -->
  <xacro:property name="stator_size" value="0.102 0.102 0.102"/>
  <xacro:property name="rotor_length" value="0.010"/>
  <xacro:property name="rotor_radius" value="0.025"/>
  <xacro:property name="angle_size" value="0.025 0.002 0.002"/>

  <!-- Define the Macro with a single parameter "prefix" -->
  <xacro:macro name="qube" params="prefix">

    <!-- Links with prefixed names -->
    <link name="${prefix}stator_link">
      <visual>
        <geometry>
          <box size="${stator_size}"/>
        </geometry>
        <material name="black">
          <color rgba="0 0 0 1"/>
        </material>
      </visual>
    </link>

    <link name="${prefix}rotor_link">
      <visual>
        <geometry>
          <cylinder length="${rotor_length}" radius="${rotor_radius}"/>
        </geometry>
        <material name="red">
          <color rgba="1 0 0 1"/>
        </material>
      </visual>
    </link>

    <link name="${prefix}angle_link">
      <visual>
        <geometry>
          <box size="${angle_size}"/>
        </geometry>
        <material name="white">
          <color rgba="1 1 1 1"/>
        </material>
      </visual>
    </link>

    <!-- Joints with prefixed names -->
    <joint name="${prefix}stator_joint" type="fixed">
      <parent link="base_link"/>
      <child link="${prefix}stator_link"/>
      <origin xyz="0 0 0.050" rpy="0 0 0"/>
    </joint>

<joint name="${prefix}motor_joint" type="continuous">
  <parent link="${prefix}stator_link"/>
  <child link="${prefix}rotor_link"/>
  <origin xyz="0 0 0.05" rpy="0 0 0"/>
  <axis xyz="0 0 1"/>
</joint>

    <!-- ros2_control transmission configuration -->
    <ros2_control name="motor_joint" type="transmission_interface/SimpleTransmission">
      <joint name="${prefix}motor_joint">
        <command_interface name="velocity"/>
        <state_interface name="velocity"/>
        <state_interface name="position"/>
      </joint>
    </ros2_control>

    <joint name="${prefix}indicator" type="fixed">
      <parent link="${prefix}rotor_link"/>
      <child link="${prefix}angle_link"/>
      <origin xyz="0.012 0 0.005" rpy="0 0 0"/>
    </joint>

  </xacro:macro>

  <!-- Define Static Links -->
  <link name="base_link"/>

</robot>
